Workbook

Sheet Weekly Report
B5: As of Date: 2024/10/01
C7: 45444 | E7: =C7+31 -> 45475 | G7: =E7+31 -> 45506 | I7: =G7+31 -> 45537 | K7: =I7+31 -> 45568 | M7: =K7+31 -> 45599 | O7: =M7+31 -> 45630 | Q7: =O7+31 -> 45661 | S7: =Q7+31 -> 45692 | U7: =S7+31 -> 45723 | W7: =U7+31 -> 45754 | Y7: =W7+31 -> 45785 | AA7: =Y7+31 -> 45816
B9: TBOS System
B15: wk ended | C15: 45524 | D15: =C15+7 -> 45531 | E15: =D15+7 -> 45538 | F15: =E15+7 -> 45545 | G15: =F15+7 -> 45552 | H15: =G15+7 -> 45559 | I15: =H15+7 -> 45566 | J15: =I15+7 -> 45573 | K15: =J15+7 -> 45580 | ... AF15: =AE15+7 -> 45727
B23: Plan (weekly) | C23: 0 | D23: 3 | E23: 7 | F23: 10 | G23: 12 | H23: 10 | I23: 8 | J23: 11 | K23: 9 | L23: 9 | M23: 9 | N23: 7 | O23: 4 | P23: 0 | Q23: 0 | R23: 0 | S23: 0 | T23: 0 | U23: 0 | V23: 0 | W23: 0 | X23: 0 | Y23: 0 | Z23: 0 | AA23: 0 | AB23: 0 | AC23: 0 | AD23: 0 | AE23: 0 | AF23: 0
B24: Result (weekly) | C24: 0 | D24: 3 | E24: 7 | F24: 9 | G24: 13 | H24: 10 | I24: 8 | J24: 0 | K24: 0 | L24: 0 | M24: 0 | N24: 0 | O24: 0 | P24: 0 | Q24: 0 | R24: 0 | S24: 0 | T24: 0 | U24: 0 | V24: 0 | W24: 0 | X24: 0 | Y24: 0 | Z24: 0 | AA24: 0 | AB24: 0 | AC24: 0 | AD24: 0 | AE24: 0 | AF24: 0
B25: Difference (weekly) | C25: =C24-C23 -> 0 | D25: =D24-D23 -> 0 | E25: =E24-E23 -> 0 | F25: =F24-F23 -> -1 | G25: =G24-G23 -> 1 | H25: =H24-H23 -> 0 | I25: =I24-I23 -> 0 | J25: =J24-J23 -> -11 | ... AF25: =AF24-AF23 -> 0
B26: Plan (accum.) | C26: =C23 -> 0 | D26: =C26+D23 -> 3 | E26: =D26+E23 -> 10 | F26: =E26+F23 -> 20 | G26: =F26+G23 -> 32 | H26: =G26+H23 -> 42 | I26: =H26+I23 -> 50 | J26: =I26+J23 -> 61 | K26: =J26+K23 -> 70 | ... AF26: =AE26+AF23 -> 99
B27: Result (accum.) | C27: =C24 -> 0 | D27: =C27+D24 -> 3 | E27: =D27+E24 -> 10 | F27: =E27+F24 -> 19 | G27: =F27+G24 -> 32 | H27: =G27+H24 -> 42 | I27: =H27+I24 -> 50 | J27: =I27+J24 -> 50 | K27: =J27+K24 -> 50 | ... AF27: =AE27+AF24 -> 50
B28: Difference (accum.) | C28: =C27-C26 -> 0 | D28: =D27-D26 -> 0 | E28: =E27-E26 -> 0 | F28: =F27-F26 -> -1 | G28: =G27-G26 -> 0 | H28: =H27-H26 -> 0 | I28: =I27-I26 -> 0 | J28: =J27-J26 -> -11 | ... AF28: =AF27-AF26 -> -49
C30: =C15 -> 45524 | D30: =C30+7 -> 45531 | E30: =D30+7 -> 45538 | F30: =E30+7 -> 45545 | G30: =F30+7 -> 45552 | H30: =G30+7 -> 45559 | I30: =H30+7 -> 45566 | J30: =I30+7 -> 45573 | K30: =J30+7 -> 45580 | ... AF30: =AE30+7 -> 45727
B38: Test Plan (weekly) | C38: 0 | D38: 0 | E38: 0 | F38: 0 | G38: 27 | H38: 210 | I38: 120 | J38: 92 | K38: 89 | L38: 101 | M38: 133 | N38: 34 | O38: 0 | P38: 0 | Q38: 0 | R38: 0 | S38: 0 | T38: 0
B39: Test Result (weekly) | C39: 0 | D39: 0 | E39: 0 | F39: 0 | G39: 27 | H39: 210 | I39: 120 | J39: 0 | K39: 0 | L39: 0 | M39: 0 | N39: 0 | O39: 0 | P39: 0 | Q39: 0 | R39: 0 | S39: 0 | T39: 0
B40: Test Plan (accum.) | C40: =C38 -> 0 | D40: =C40+D38 -> 0 | E40: =D40+E38 -> 0 | F40: =E40+F38 -> 0 | G40: =F40+G38 -> 27 | H40: =G40+H38 -> 237 | I40: =H40+I38 -> 357 | J40: =I40+J38 -> 449 | K40: =J40+K38 -> 538 | ... AF40: =AE40+AF38 -> 806
B41: Test Result (accum.) | C41: =C39 -> 0 | D41: =C41+D39 -> 0 | E41: =D41+E39 -> 0 | F41: =E41+F39 -> 0 | G41: =F41+G39 -> 27 | H41: =G41+H39 -> 237 | I41: =H41+I39 -> 357 | J41: =I41+J39 -> 357 | K41: =J41+K39 -> 357 | ... AF41: =AE41+AF39 -> 357
B42: Test Plan (remained) | C42: =$K$52 - C40 -> 779 | D42: =$K$52 - D40 -> 779 | E42: =$K$52 - E40 -> 779 | F42: =$K$52 - F40 -> 779 | G42: =$K$52 - G40 -> 752 | H42: =$K$52 - H40 -> 542 | I42: =$K$52 - I40 -> 422 | J42: =$K$52 - J40 -> 330 | ... AF42: =$K$52 - AF40 -> -27
B43: Test Result (remained) | C43: =$K$52 - C41 -> 779 | D43: =$K$52 - D41 -> 779 | E43: =$K$52 - E41 -> 779 | F43: =$K$52 - F41 -> 779 | G43: =$K$52 - G41 -> 752 | H43: =$K$52 - H41 -> 542 | I43: =$K$52 - I41 -> 422 | J43: =$K$52 - J41 -> 422 | ... AF43: =$K$52 - AF41 -> 422
B44: Inc Detected | C44: 0 | D44: 0 | E44: 0 | F44: 0 | G44: 5 | H44: 33 | I44: 9 | J44: 0 | K44: 0 | L44: 0 | M44: 0 | N44: 0 | O44: 0 | P44: 0 | Q44: 0 | R44: 0 | S44: 0 | T44: 0
B45: Inc Fixed | C45: 0 | D45: 0 | E45: 0 | F45: 0 | G45: 5 | H45: 33 | I45: 9 | J45: 0 | K45: 0 | L45: 0 | M45: 0 | N45: 0 | O45: 0 | P45: 0 | Q45: 0 | R45: 0 | S45: 0 | T45: 0
B46: Inc Detected (accum.) | C46: =C44 -> 0 | D46: =C46+D44 -> 0 | E46: =D46+E44 -> 0 | F46: =E46+F44 -> 0 | G46: =F46+G44 -> 5 | H46: =G46+H44 -> 38 | I46: =H46+I44 -> 47 | J46: =I46+J44 -> 47 | K46: =J46+K44 -> 47 | ... AF46: =AE46+AF44 -> 47
B47: Inc Fixed (accum.) | C47: =C45 -> 0 | D47: =C47+D45 -> 0 | E47: =D47+E45 -> 0 | F47: =E47+F45 -> 0 | G47: =F47+G45 -> 5 | H47: =G47+H45 -> 38 | I47: =H47+I45 -> 47 | J47: =I47+J45 -> 47 | K47: =J47+K45 -> 47 | ... AF47: =AE47+AF45 -> 47
B48: Inc Remained | C48: =C46-C47 -> 0 | D48: =D46-D47 -> 0 | E48: =E46-E47 -> 0 | F48: =F46-F47 -> 0 | G48: =G46-G47 -> 0 | H48: =H46-H47 -> 0 | I48: =I46-I47 -> 0 | J48: =J46-J47 -> 0 | ... AF48: =AF46-AF47 -> 0
C51: Total | E51: +/- | G51: Total (Last wk) | I51: Total FP | K51: Total Test Cases
B52: Programming | C52: 30x3 | E52: 0 | G52: 90 | I52: 102 | K52: 779 | R52: Open Issue (This wk) | U52: Remained (Last wk) | X52: New (This wk) | AA52: Solved (This wk)
R53: =U53+X53-AA53 -> 2 | U53: 2 | X53: 1 | AA53: 1
B54: Programming Status (Function) | C54: Result | I54: Plan (Accm.) | K54: Progress (Days) | M54: Evaluation
C55: Accum. (This wk) | E55: Accum. (Last wk) | G55: Achieve (This wk) | U55: Route A (approved) | AA55: Route B (approved)
B56: Start | C56: =E56+G56 -> 19 | E56: 16 | G56: 3 | I56: 19 | K56: 0 | M56: B | U56: Accum. (This wk) | W56: New (This wk) | Y56: Accum. (Last wk) | AA56: Accum. (This wk) | AC56: New (This wk) | AE56: Accum. (Last wk)
B57: Finish | C57: =E57+G57 -> 16 | E57: 16 | G57: 0 | I57: 16 | K57: 0 | M57: B
B58: Tested | C58: =E58+G58 -> 15 | E58: 10 | G58: 5 | I58: 15 | K58: 0 | M58: B | R58: Change Request (PU) | U58: 0 | W58: =U58-Y58 -> 0 | Y58: 0 | AA58: 0 | AC58: =AA58-AE58 -> 0 | AE58: 0
B59: Total | C59: =SUM(C56:D58) -> 50 | E59: =SUM(E56:F58) -> 42 | G59: =SUM(G56:H58) -> 8 | I59: =SUM(I56:J58) -> 50 | K59: 0 | M59: B
R60: Test Script Creation | U60: Total Target Test Items | X60: Created Test Items | AA60: % of Created
B61: Quality | C61: Accum Tested FP | E61: Target per FP | G61: Test Density (/FP) | I61: Inc Detection (/FP) | K61: Accum. (This wk) | M61: Accum. (Last wk) | O61: Achieve (This wk) | R61: IFT (Test case) | U61: 0 | X61: 0 | AA61: =IF(U61<>0, X61/U61, 0) -> 0
R62: BCT (Test scenario) | U62: 0 | X62: 0 | AA62: =IF(U62<>0, X62/U62, 0) -> 0
B63: Tested Cases (Screen) | C63: 26.8 | E63: 10-14 | G63: =IF(C63=0,0,K63/C63) -> 3.7313433 | K63: =M63+O63 -> 100 | M63: 81.5 | O63: 18.5
B64: Tested Cases (Batch) | C64: 66.9 | E64: 4-8 | G64: =IF(C64=0,0,K64/C64) -> 3.3781764 | K64: =M64+O64 -> 226 | M64: 155 | O64: 71
B65: Tested Cases (Report) | C65: 7.5 | E65: 4-8 | G65: =IF(C65=0,0,K65/C65) -> 4 | K65: =M65+O65 -> 30 | M65: 0 | O65: 30
B66: Incident Detect (Screen) | E66: 3 | I66: =IF(C63=0,0,K66/C63) -> 1.1567164 | K66: =M66+O66 -> 31 | M66: 22 | O66: 9
B67: Incident Detect (Batch) | E67: 2 | I67: =IF(C64=0,0,K67/C64) -> 0.23916293 | K67: =M67+O67 -> 16 | M67: 16 | O67: 0
B68: Incident Detect (Report) | E68: 1.2 | I68: =IF(C65=0,0,K68/C65) -> 0 | K68: =M68+O68 -> 0 | M68: 0 | O68: 0
...

Sheet PB Curve
C41: ='Weekly Report'!C15 -> 45524 | D41: ='Weekly Report'!D15 -> 45531 | E41: ='Weekly Report'!E15 -> 45538 | F41: ='Weekly Report'!F15 -> 45545 | G41: ='Weekly Report'!G15 -> 45552 | H41: ='Weekly Report'!H15 -> 45559 | I41: ='Weekly Report'!I15 -> 45566 | J41: ='Weekly Report'!J15 -> 45573 | ... AF41: ='Weekly Report'!AF15 -> 45727
B42: Remained Test Cases (plan) | C42: ='Weekly Report'!C42 -> 779 | D42: ='Weekly Report'!D42 -> 779 | E42: ='Weekly Report'!E42 -> 779 | F42: ='Weekly Report'!F42 -> 779 | G42: ='Weekly Report'!G42 -> 752 | H42: ='Weekly Report'!H42 -> 542 | I42: ='Weekly Report'!I42 -> 422 | J42: ='Weekly Report'!J42 -> 330 | ... AF42: ='Weekly Report'!AF42 -> -27
B43: Remained Test Cases (result) | C43: ='Weekly Report'!C43 -> 779 | D43: ='Weekly Report'!D43 -> 779 | E43: ='Weekly Report'!E43 -> 779 | F43: ='Weekly Report'!F43 -> 779 | G43: ='Weekly Report'!G43 -> 752 | H43: ='Weekly Report'!H43 -> 542 | I43: ='Weekly Report'!I43 -> 422 | J43: ='Weekly Report'!J43 -> 422 | ... AF43: ='Weekly Report'!AF43 -> 422
B44: Accum Test Cases (result) | C44: ='Weekly Report'!C41 -> 0 | D44: ='Weekly Report'!D41 -> 0 | E44: ='Weekly Report'!E41 -> 0 | F44: ='Weekly Report'!F41 -> 0 | G44: ='Weekly Report'!G41 -> 27 | H44: ='Weekly Report'!H41 -> 237 | I44: ='Weekly Report'!I41 -> 357 | J44: ='Weekly Report'!J41 -> 357 | ... AF44: ='Weekly Report'!AF41 -> 357
B45: Inc-Detected (standard) | C45: =IF('Weekly Report'!$K$52=0, 0, CEILING(2.3 * 'Weekly Report'!$I$52 * C44 / 'Weekly Report'!$K$52, 1)) -> 0 | D45: =IF('Weekly Report'!$K$52=0, 0, CEILING(2.3 * 'Weekly Report'!$I$52 * D44 / 'Weekly Report'!$K$52, 1)) -> 0 | E45: =IF('Weekly Report'!$K$52=0, 0, CEILING(2.3 * 'Weekly Report'!$I$52 * E44 / 'Weekly Report'!$K$52, 1)) -> 0 | F45: =IF('Weekly Report'!$K$52=0, 0, CEILING(2.3 * 'Weekly Report'!$I$52 * F44 / 'Weekly Report'!$K$52, 1)) -> 0 | G45: =IF('Weekly Report'!$K$52=0, 0, CEILING(2.3 * 'Weekly Report'!$I$52 * G44 / 'Weekly Report'!$K$52, 1)) -> 9 | H45: =IF('Weekly Report'!$K$52=0, 0, CEILING(2.3 * 'Weekly Report'!$I$52 * H44 / 'Weekly Report'!$K$52, 1)) -> 72 | I45: =IF('Weekly Report'!$K$52=0, 0, CEILING(2.3 * 'Weekly Report'!$I$52 * I44 / 'Weekly Report'!$K$52, 1)) -> 108 | J45: =IF('Weekly Report'!$K$52=0, 0, CEILING(2.3 * 'Weekly Report'!$I$52 * J44 / 'Weekly Report'!$K$52, 1)) -> 108 | ... AF45: =IF('Weekly Report'!$K$52=0, 0, CEILING(2.3 * 'Weekly Report'!$I$52 * AF44 / 'Weekly Report'!$K$52, 1)) -> 108
B46: Inc detected (accum) | C46: ='Weekly Report'!C46 -> 0 | D46: ='Weekly Report'!D46 -> 0 | E46: ='Weekly Report'!E46 -> 0 | F46: ='Weekly Report'!F46 -> 0 | G46: ='Weekly Report'!G46 -> 5 | H46: ='Weekly Report'!H46 -> 38 | I46: ='Weekly Report'!I46 -> 47 | J46: ='Weekly Report'!J46 -> 47 | ... AF46: ='Weekly Report'!AF46 -> 47
B47: Inc fixed (accum) | C47: ='Weekly Report'!C47 -> 0 | D47: ='Weekly Report'!D47 -> 0 | E47: ='Weekly Report'!E47 -> 0 | F47: ='Weekly Report'!F47 -> 0 | G47: ='Weekly Report'!G47 -> 5 | H47: ='Weekly Report'!H47 -> 38 | I47: ='Weekly Report'!I47 -> 47 | J47: ='Weekly Report'!J47 -> 47 | ... AF47: ='Weekly Report'!AF47 -> 47

Sheet Usage Guideline
B1: Phase | O1: Project Name | AB1: TMAP Standard | CN1: Page
B2: Block Name | O2: TMAP Management Standard | AI2: Function Name | AT2: 04 Progress Management | BW2: Created | CC2: 39174 | CN2: By | CR2: Rujipun
B3: Document Name | O3: Weekly Report PU | AI3: Title | AT3: Usage Guideline | BW3: Updated | CC3: 40060 | CN3: By | CR3: Anan
B5: Usage Guideline : Weekly Report PU
C7: 1. | E7: Template Layout
C53: 2. | E53: How to Fill up
E54: 2.1 | H54: Header
H67: Step 1 : | N67: Fill in the project and System Name, e.g. TMAP-EM : FISM, TMAP Standards : Management Standard
H68: Step 2 : | N68: Fill in the date of making the report. Date of making the report is usually the date of one day before the weekly progress meeting date.
H69: Step 3 : | N69: Get the signature of Vendor PIC and ISD PIC of the project. Vendor PIC and ISD PIC are required to check the correctness of the progress report before signing.
E72: 2.2 | H72: Overview Schedule
H82: Step 1 : | N82: Fill in System Name
H83: Step 2 : | N83: Draw overview schedule of the project for all phases
H84: Step 3 : | N84: Update "Progress Line" to reflect and show the progress or delay of the project
E93: 2.3 | H93: Programming Statistics
H115: Step 1 : | N115: Fill in Report Creation Date. Usually, it is the date of one day before the weekly meeting date.
H117: Step 2 : | N117: Fill in weekly plan (all weeks of the plan). The value to fill is the summation of all tasks measured in the unit of Indicator of the phase, and it can be obtained from
N118: Total Plan row in Daily Progress Report, as an example displayed below:
N120: Daily Progress | W120: :
N121: Report
N124: Weekly | W124: :
N125: Report
N129: For PU, there are three types of tasks, i.e. 1) Start Coding, 2) Finish Coding, and 3) Tested. Unit of Indicator of Coding is Function.
N130: Note : TMAP Standard provides Daily Progress template for planning and tracking the progress. Please refer to the template.
H134: Step 3 : | N134: Fill in weekly result (for the week to report). The value to fill is also the summation of all tasks measured in the unit of Indicator of the phase, and it can be
N135: obtained from Total Result row in Daily Progress Report, as an example displayed below:
N137: Daily Progress | W137: :
N138: Report
N141: Weekly | W141: :
N142: Report
H147: Note-1 : | N147: Workload Ratio of tasks is the ratio of workload of each task needed to be completed in order to finish the phase. In PU, there are three basic
N148: tasks, i.e. 1) Start Coding, 2) Finish Coding, and 3) Tested. Here, we assume all tasks have the same workload in Standard. That means
N149: Coding have the same workload as Testing.
H151: Note-2 : | N151: In case that the phase is very short, this can be daily instead of weekly
H153: Note-3 : | N153: Difference (weekly and accum), Plan (accum) and Result (accum) are automatically calculated
H155: Note-4 : | N155: Accum Plan is equal to Accum Result when the phase is finished.
E174: 2.4 | H174: Testing and Quality Statistics
H198: Step 1 : | N198: Fill in Report Creation Date. Usually, it is the date of one day before the weekly meeting date.
H200: Step 2 : | N200: Fill in weekly plan (all weeks of the plan). The value to fill is the number of test cases planned to test on that week , and it can be obtained from
N201: Total Plan (Tested) row in Daily Progress Report, as an example displayed below:
...

Sheet PB Curve Guideline
B5: PU Weekly Report Guideline
B7: [How to understand PB Curve]
C8: In the software development, we wish to have the incident detected curve as shown in Figure 1, while we plan to test the application in three steps
C9: at different test rates, i.e. 1) Learning Period: the rate of testing is slow in order to prepare, learn, and get used to the testing, 2) Adjusted Period:
C10: the rate of testing is in full speed, 3) Fixing Period: the rate of testing is slow down in order to have time for fixing incidents.
CF15: 38516 | CG15: =CF15+7 -> 38523 | CH15: =CG15+7 -> 38530 | CI15: =CH15+7 -> 38537 | CJ15: =CI15+7 -> 38544 | CK15: =CJ15+7 -> 38551 | CL15: =CK15+7 -> 38558 | CM15: =CL15+7 -> 38565 | CN15: =CM15+7 -> 38572 | ... CT15: =CS15+7 -> 38614
CE16: Remained Test Cases (plan) | CF16: 300 | CG16: 290 | CH16: 280 | CI16: 270 | CJ16: 240 | CK16: 210 | CL16: 180 | CM16: 150 | CN16: 120 | CO16: 90 | CP16: 60 | CQ16: 30 | CR16: 20 | CS16: 10 | CT16: 0
CE17: Incident detected (accum) | CF17: 0 | CG17: 1 | CH17: 2 | CI17: 3 | CJ17: 6 | CK17: 9 | CL17: 12 | CM17: 15 | CN17: 18 | CO17: 21 | CP17: 24 | CQ17: 27 | CR17: 28 | CS17: 29 | CT17: 30
C40: However, in the actual situation the curves are various and different from the ideal. We can draw these curves, see the tendency and compare with
C41: the standard curve in order to predict and be alerted for the possible problems and control the software quality. We call these curves "PB Curve".
C43: PB curve is used to see the tendency of developed software in terms of the number of test cases and the number of incidents. Normally, it consists
C44: of four graphs, i.e. 1) Remained Test Cases (plan), 2) Remained Test Cases (result), 3) Incident detected (standard), and 4) Incident detected
C45: (accum). But in TMAP weekly report, "Incident Fixed (accum)" is added to show the tendency of fixing the incidents.
CF54: 38516 | CG54: =CF54+7 -> 38523 | CH54: =CG54+7 -> 38530 | CI54: =CH54+7 -> 38537 | CJ54: =CI54+7 -> 38544 | CK54: =CJ54+7 -> 38551 | CL54: =CK54+7 -> 38558 | CM54: =CL54+7 -> 38565 | CN54: =CM54+7 -> 38572 | ... CT54: =CS54+7 -> 38614
CE55: Remained Test Cases (plan) | CF55: 300 | CG55: 300 | CH55: 280 | CI55: 265 | CJ55: 245 | CK55: 215 | CL55: 200 | CM55: 175 | CN55: 140 | CO55: 110 | CP55: 65 | CQ55: 35 | CR55: 10 | CS55: 0 | CT55: 0
CE56: Remained Test Cases (result) | CF56: 300 | CG56: 300 | CH56: 294 | CI56: 288 | CJ56: 267 | CK56: 230 | CL56: 205 | CM56: 173 | CN56: 137 | CO56: 105 | CP56: 70 | CQ56: 36 | CR56: 12 | CS56: 12 | CT56: 12
CE57: Accum Test Cases (plan) | CF57: =300 -CF55 -> 0 | CG57: =300 -CG55 -> 0 | CH57: =300 -CH55 -> 20 | CI57: =300 -CI55 -> 35 | CJ57: =300 -CJ55 -> 55 | CK57: =300 -CK55 -> 85 | CL57: =300 -CL55 -> 100 | CM57: =300 -CM55 -> 125 | ... CT57: =300 -CT55 -> 300
CE58: Inc-Detected (standard) | CF58: 0 | CG58: =CEILING(2.3*30*CG57/ 300, 1) -> 0 | CH58: =CEILING(2.3*30*CH57/ 300, 1) -> 5 | CI58: =CEILING(2.3*30*CI57/ 300, 1) -> 9 | CJ58: =CEILING(2.3*30*CJ57/ 300, 1) -> 13 | CK58: =CEILING(2.3*30*CK57/ 300, 1) -> 20 | CL58: =CEILING(2.3*30*CL57/ 300, 1) -> 23 | CM58: =CEILING(2.3*30*CM57/ 300, 1) -> 29 | CN58: =CEILING(2.3*30*CN57/ 300, 1) -> 37 | ... CT58: =CEILING(2.3*30*CT57/ 300, 1) -> 69
CE59: Inc detected (accum) | CF59: 0 | CG59: 0 | CH59: 1 | CI59: 3 | CJ59: 5 | CK59: 7 | CL59: 22 | CM59: 38 | CN59: 45 | CO59: 46 | CP59: 52 | CQ59: 65 | CR59: 72 | CS59: 72 | CT59: 72
CE60: Inc fixed (accum) | CF60: 0 | CG60: 0 | CH60: 0 | CI60: 2 | CJ60: 4 | CK60: 7 | CL60: 13 | CM60: 23 | CN60: 32 | CO60: 43 | CP60: 48 | CQ60: 58 | CR60: 70 | CS60: 70 | CT60: 70
B84: [Standard Quality Indicator]
C86: The PU standard quality indicators are shown as follows:
O88: FP Base for Batch, Screen, and Report -- per FP
F89: Batch | O89: Quality verification | AH89: Test Case
F90: (1FP=200 Step) | AA90: Case/FP | AH90: 6+/-2 (4-8)
O91: Quality Indicator | AA91: Incident/FP | AH91: 2
F92: Screen | O92: Quality verification | AH92: Test Case
AA93: Cases | AH93: 12+/-2 (10-14)
O94: Quality Indicator | AA94: Incidents | AH94: 3
F95: Report | O95: Quality verification | AH95: Test Case
F96: Normal | AA96: Cases | AH96: 6+/-2 (4-8)
O97: Quality Indicator | AA97: Incidents | AH97: 1.2
F98: Report | O98: Quality verification | AH98: Test Case
F99: Complex | AA99: Cases | AH99: 12+/-2 (10-14)
O100: Quality Indicator | AA100: Incidents | AH100: 2.4

Sheet Example_Weekly Report
B5: As of Date: 2005/10/3
C7: 38718 | E7: =C7+31 -> 38749 | G7: =E7+31 -> 38780 | I7: =G7+31 -> 38811 | K7: =I7+31 -> 38842 | M7: =K7+31 -> 38873 | O7: =M7+31 -> 38904 | Q7: =O7+31 -> 38935 | S7: =Q7+31 -> 38966 | U7: =S7+31 -> 38997 | W7: =U7+31 -> 39028 | Y7: =W7+31 -> 39059 | AA7: =Y7+31 -> 39090
B9: XXX System
B15: wk ended | C15: 38516 | D15: =C15+7 -> 38523 | E15: =D15+7 -> 38530 | F15: =E15+7 -> 38537 | G15: =F15+7 -> 38544 | H15: =G15+7 -> 38551 | I15: =H15+7 -> 38558 | J15: =I15+7 -> 38565 | K15: =J15+7 -> 38572 | ... AF15: =AE15+7 -> 38719
B23: Plan (weekly) | C23: 0 | D23: 0 | E23: 0 | F23: 0 | G23: 0 | H23: 0 | I23: 9 | J23: 24 | K23: 18 | L23: 21 | M23: 18 | N23: 24 | O23: 21 | P23: 24 | Q23: 21 | R23: 12 | S23: 15 | T23: 12 | U23: 0 | V23: 0 | W23: 0 | X23: 0 | Y23: 0 | Z23: 0 | AA23: 0 | AB23: 0 | AC23: 0 | AD23: 0 | AE23: 0 | AF23: 0
B24: Result (weekly) | C24: 0 | D24: 0 | E24: 0 | F24: 0 | G24: 0 | H24: 0 | I24: 9 | J24: 24 | K24: 18 | L24: 24 | M24: 24 | N24: 15 | O24: 21 | P24: 27 | Q24: 24 | R24: 11 | S24: 8 | T24: 0 | U24: 0 | V24: 0 | W24: 0 | X24: 0 | Y24: 0 | Z24: 0 | AA24: 0 | AB24: 0 | AC24: 0 | AD24: 0 | AE24: 0 | AF24: 0
B25: Difference (weekly) | C25: =C24-C23 -> 0 | D25: =D24-D23 -> 0 | E25: =E24-E23 -> 0 | F25: =F24-F23 -> 0 | G25: =G24-G23 -> 0 | H25: =H24-H23 -> 0 | I25: =I24-I23 -> 0 | J25: =J24-J23 -> 0 | ... AF25: =AF24-AF23 -> 0
B26: Plan (accum.) | C26: =C23 -> 0 | D26: =C26+D23 -> 0 | E26: =D26+E23 -> 0 | F26: =E26+F23 -> 0 | G26: =F26+G23 -> 0 | H26: =G26+H23 -> 0 | I26: =H26+I23 -> 9 | J26: =I26+J23 -> 33 | K26: =J26+K23 -> 51 | ... AF26: =AE26+AF23 -> 219
B27: Result (accum.) | C27: =C24 -> 0 | D27: =C27+D24 -> 0 | E27: =D27+E24 -> 0 | F27: =E27+F24 -> 0 | G27: =F27+G24 -> 0 | H27: =G27+H24 -> 0 | I27: =H27+I24 -> 9 | J27: =I27+J24 -> 33 | K27: =J27+K24 -> 51 | ... AF27: =AE27+AF24 -> 205
B28: Difference (accum.) | C28: =C27-C26 -> 0 | D28: =D27-D26 -> 0 | E28: =E27-E26 -> 0 | F28: =F27-F26 -> 0 | G28: =G27-G26 -> 0 | H28: =H27-H26 -> 0 | I28: =I27-I26 -> 0 | J28: =J27-J26 -> 0 | ... AF28: =AF27-AF26 -> -14
C30: =C15 -> 38516 | D30: =C30+7 -> 38523 | E30: =D30+7 -> 38530 | F30: =E30+7 -> 38537 | G30: =F30+7 -> 38544 | H30: =G30+7 -> 38551 | I30: =H30+7 -> 38558 | J30: =I30+7 -> 38565 | K30: =J30+7 -> 38572 | ... AF30: =AE30+7 -> 38719
B38: Test Plan (weekly) | C38: 0 | D38: 0 | E38: 0 | F38: 0 | G38: 0 | H38: 0 | I38: 16 | J38: 25 | K38: 30 | L38: 130 | M38: 125 | N38: 160 | O38: 250 | P38: 120 | Q38: 120 | R38: 180 | S38: 110 | T38: 150
B39: Test Result (weekly) | C39: 0 | D39: 0 | E39: 0 | F39: 0 | G39: 0 | H39: 0 | I39: 16 | J39: 25 | K39: 30 | L39: 130 | M39: 125 | N39: 160 | O39: 250 | P39: 120 | Q39: 120 | R39: 180 | S39: 90 | T39: 0
B40: Test Plan (accum.) | C40: =C38 -> 0 | D40: =C40+D38 -> 0 | E40: =D40+E38 -> 0 | F40: =E40+F38 -> 0 | G40: =F40+G38 -> 0 | H40: =G40+H38 -> 0 | I40: =H40+I38 -> 16 | J40: =I40+J38 -> 41 | K40: =J40+K38 -> 71 | ... AF40: =AE40+AF38 -> 1416
B41: Test Result (accum.) | C41: =C39 -> 0 | D41: =C41+D39 -> 0 | E41: =D41+E39 -> 0 | F41: =E41+F39 -> 0 | G41: =F41+G39 -> 0 | H41: =G41+H39 -> 0 | I41: =H41+I39 -> 16 | J41: =I41+J39 -> 41 | K41: =J41+K39 -> 71 | ... AF41: =AE41+AF39 -> 1246
B42: Test Plan (remained) | C42: =$K$52 - C40 -> 1416 | D42: =$K$52 - D40 -> 1416 | E42: =$K$52 - E40 -> 1416 | F42: =$K$52 - F40 -> 1416 | G42: =$K$52 - G40 -> 1416 | H42: =$K$52 - H40 -> 1416 | I42: =$K$52 - I40 -> 1400 | J42: =$K$52 - J40 -> 1375 | ... AF42: =$K$52 - AF40 -> 0
B43: Test Result (remained) | C43: =$K$52 - C41 -> 1416 | D43: =$K$52 - D41 -> 1416 | E43: =$K$52 - E41 -> 1416 | F43: =$K$52 - F41 -> 1416 | G43: =$K$52 - G41 -> 1416 | H43: =$K$52 - H41 -> 1416 | I43: =$K$52 - I41 -> 1400 | J43: =$K$52 - J41 -> 1375 | ... AF43: =$K$52 - AF41 -> 170
B44: Inc Detected | C44: 0 | D44: 0 | E44: 0 | F44: 0 | G44: 0 | H44: 0 | I44: 0 | J44: 1 | K44: 9 | L44: 13 | M44: 25 | N44: 31 | O44: 38 | P44: 43 | Q44: 20 | R44: 55 | S44: 42 | T44: 0
B45: Inc Fixed | C45: 0 | D45: 0 | E45: 0 | F45: 0 | G45: 0 | H45: 0 | I45: 0 | J45: 1 | K45: 8 | L45: 10 | M45: 26 | N45: 23 | O45: 8 | P45: 71 | Q45: 29 | R45: 46 | S45: 39 | T45: 0
B46: Inc Detected (accum.) | C46: =C44 -> 0 | D46: =C46+D44 -> 0 | E46: =D46+E44 -> 0 | F46: =E46+F44 -> 0 | G46: =F46+G44 -> 0 | H46: =G46+H44 -> 0 | I46: =H46+I44 -> 0 | J46: =I46+J44 -> 1 | K46: =J46+K44 -> 10 | ... AF46: =AE46+AF44 -> 277
B47: Inc Fixed (accum.) | C47: =C45 -> 0 | D47: =C47+D45 -> 0 | E47: =D47+E45 -> 0 | F47: =E47+F45 -> 0 | G47: =F47+G45 -> 0 | H47: =G47+H45 -> 0 | I47: =H47+I45 -> 0 | J47: =I47+J45 -> 1 | K47: =J47+K45 -> 9 | ... AF47: =AE47+AF45 -> 261
B48: Inc Remained | C48: =C46-C47 -> 0 | D48: =D46-D47 -> 0 | E48: =E46-E47 -> 0 | F48: =F46-F47 -> 0 | G48: =G46-G47 -> 0 | H48: =H46-H47 -> 0 | I48: =I46-I47 -> 0 | J48: =J46-J47 -> 0 | ... AF48: =AF46-AF47 -> 16
C51: Total | E51: +/- | G51: Total (Last wk) | I51: Total FP | K51: Total Test Cases
B52: Programming | C52: 73x3 | E52: 0 | G52: 219 | I52: 130 | K52: 1416 | R52: Open Issue (This wk) | U52: Remained (Last wk) | X52: New (This wk) | AA52: Solved (This wk)
R53: =U53+X53-AA53 -> 0 | U53: 0 | X53: 0 | AA53: 0
B54: Programming Status (Function) | C54: Result | I54: Plan (Accm.) | K54: Progress (Days) | M54: Evaluation
C55: Accum. (This wk) | E55: Accum. (Last wk) | G55: Achieve (This wk) | U55: Route A (approved) | AA55: Route B (approved)
B56: Start | C56: =E56+G56 -> 69 | E56: 67 | G56: 2 | I56: 69 | K56: 0 | M56: B | U56: Accum. (This wk) | W56: New (This wk) | Y56: Accum. (Last wk) | AA56: Accum. (This wk) | AC56: New (This wk) | AE56: Accum. (Last wk)
B57: Finish | C57: =E57+G57 -> 69 | E57: 67 | G57: 2 | I57: 69 | K57: 0 | M57: B
B58: Tested | C58: =E58+G58 -> 67 | E58: 63 | G58: 4 | I58: 69 | K58: -1 | M58: C | R58: Change Request (PU) | U58: 0 | W58: =U58-Y58 -> 0 | Y58: 0 | AA58: 0 | AC58: =AA58-AE58 -> 0 | AE58: 0
B59: Total | C59: =SUM(C56:D58) -> 205 | E59: =SUM(E56:F58) -> 197 | G59: =SUM(G56:H58) -> 8 | I59: =SUM(I56:J58) -> 207 | K59: -1 | M59: C
R60: Test Script Creation | U60: Total Target Test Items | X60: Created Test Items | AA60: % of Created
B61: Quality | C61: Accum Tested FP | E61: Target per FP | G61: Test Density (/FP) | I61: Inc Detection (/FP) | K61: Accum. (This wk) | M61: Accum. (Last wk) | O61: Achieve (This wk) | R61: IFT (Test case) | U61: 100 | X61: 30 | AA61: =IF(U61<>0, X61/U61, 0) -> 0.3
R62: BCT (Test scenario) | U62: 50 | X62: 4 | AA62: =IF(U62<>0, X62/U62, 0) -> 0.08
B63: Tested Cases (Screen) | C63: 100 | E63: 10-14 | G63: =IF(C63=0,0,K63/C63) -> 10.8 | K63: =M63+O63 -> 1080 | M63: 1020 | O63: 60
B64: Tested Cases (Batch) | C64: 10 | E64: 4-8 | G64: =IF(C64=0,0,K64/C64) -> 5.4 | K64: =M64+O64 -> 54 | M64: 40 | O64: 14
B65: Tested Cases (Report) | C65: 20 | E65: 4-8 | G65: =IF(C65=0,0,K65/C65) -> 5.6 | K65: =M65+O65 -> 112 | M65: 96 | O65: 16
B66: Incident Detect (Screen) | E66: 3 | I66: =IF(C63=0,0,K66/C63) -> 1.8 | K66: =M66+O66 -> 180 | M66: 152 | O66: 28
B67: Incident Detect (Batch) | E67: 2 | I67: =IF(C64=0,0,K67/C64) -> 2.7 | K67: =M67+O67 -> 27 | M67: 23 | O67: 4
B68: Incident Detect (Report) | E68: 1.2 | I68: =IF(C65=0,0,K68/C65) -> 3.5 | K68: =M68+O68 -> 70 | M68: 60 | O68: 10
...

Sheet Example_PB Curve
C41: ='Example_Weekly Report'!C15 -> 38516 | D41: ='Example_Weekly Report'!D15 -> 38523 | E41: ='Example_Weekly Report'!E15 -> 38530 | F41: ='Example_Weekly Report'!F15 -> 38537 | G41: ='Example_Weekly Report'!G15 -> 38544 | H41: ='Example_Weekly Report'!H15 -> 38551 | I41: ='Example_Weekly Report'!I15 -> 38558 | J41: ='Example_Weekly Report'!J15 -> 38565 | ... AF41: ='Example_Weekly Report'!AF15 -> 38719
B42: Remained Test Cases (plan) | C42: ='Example_Weekly Report'!C42 -> 1416 | D42: ='Example_Weekly Report'!D42 -> 1416 | E42: ='Example_Weekly Report'!E42 -> 1416 | F42: ='Example_Weekly Report'!F42 -> 1416 | G42: ='Example_Weekly Report'!G42 -> 1416 | H42: ='Example_Weekly Report'!H42 -> 1416 | I42: ='Example_Weekly Report'!I42 -> 1400 | J42: ='Example_Weekly Report'!J42 -> 1375 | ... AF42: ='Example_Weekly Report'!AF42 -> 0
B43: Remained Test Cases (result) | C43: ='Example_Weekly Report'!C43 -> 1416 | D43: ='Example_Weekly Report'!D43 -> 1416 | E43: ='Example_Weekly Report'!E43 -> 1416 | F43: ='Example_Weekly Report'!F43 -> 1416 | G43: ='Example_Weekly Report'!G43 -> 1416 | H43: ='Example_Weekly Report'!H43 -> 1416 | I43: ='Example_Weekly Report'!I43 -> 1400 | J43: ='Example_Weekly Report'!J43 -> 1375 | ... AF43: ='Example_Weekly Report'!AF43 -> 170
B44: Accum Test Cases (result) | C44: ='Example_Weekly Report'!C41 -> 0 | D44: ='Example_Weekly Report'!D41 -> 0 | E44: ='Example_Weekly Report'!E41 -> 0 | F44: ='Example_Weekly Report'!F41 -> 0 | G44: ='Example_Weekly Report'!G41 -> 0 | H44: ='Example_Weekly Report'!H41 -> 0 | I44: ='Example_Weekly Report'!I41 -> 16 | J44: ='Example_Weekly Report'!J41 -> 41 | ... AF44: ='Example_Weekly Report'!AF41 -> 1246
B45: Inc-Detected (standard) | C45: =IF('Example_Weekly Report'!$K$52=0, 0, CEILING(2.3 * 'Example_Weekly Report'!$I$52 * C44 / 'Example_Weekly Report'!$K$52, 1)) -> 0 | D45: =IF('Example_Weekly Report'!$K$52=0, 0, CEILING(2.3 * 'Example_Weekly Report'!$I$52 * D44 / 'Example_Weekly Report'!$K$52, 1)) -> 0 | E45: =IF('Example_Weekly Report'!$K$52=0, 0, CEILING(2.3 * 'Example_Weekly Report'!$I$52 * E44 / 'Example_Weekly Report'!$K$52, 1)) -> 0 | F45: =IF('Example_Weekly Report'!$K$52=0, 0, CEILING(2.3 * 'Example_Weekly Report'!$I$52 * F44 / 'Example_Weekly Report'!$K$52, 1)) -> 0 | G45: =IF('Example_Weekly Report'!$K$52=0, 0, CEILING(2.3 * 'Example_Weekly Report'!$I$52 * G44 / 'Example_Weekly Report'!$K$52, 1)) -> 0 | H45: =IF('Example_Weekly Report'!$K$52=0, 0, CEILING(2.3 * 'Example_Weekly Report'!$I$52 * H44 / 'Example_Weekly Report'!$K$52, 1)) -> 0 | I45: =IF('Example_Weekly Report'!$K$52=0, 0, CEILING(2.3 * 'Example_Weekly Report'!$I$52 * I44 / 'Example_Weekly Report'!$K$52, 1)) -> 4 | J45: =IF('Example_Weekly Report'!$K$52=0, 0, CEILING(2.3 * 'Example_Weekly Report'!$I$52 * J44 / 'Example_Weekly Report'!$K$52, 1)) -> 9 | ... AF45: =IF('Example_Weekly Report'!$K$52=0, 0, CEILING(2.3 * 'Example_Weekly Report'!$I$52 * AF44 / 'Example_Weekly Report'!$K$52, 1)) -> 264
B46: Inc detected (accum) | C46: ='Example_Weekly Report'!C46 -> 0 | D46: ='Example_Weekly Report'!D46 -> 0 | E46: ='Example_Weekly Report'!E46 -> 0 | F46: ='Example_Weekly Report'!F46 -> 0 | G46: ='Example_Weekly Report'!G46 -> 0 | H46: ='Example_Weekly Report'!H46 -> 0 | I46: ='Example_Weekly Report'!I46 -> 0 | J46: ='Example_Weekly Report'!J46 -> 1 | ... AF46: ='Example_Weekly Report'!AF46 -> 277
B47: Inc fixed (accum) | C47: ='Example_Weekly Report'!C47 -> 0 | D47: ='Example_Weekly Report'!D47 -> 0 | E47: ='Example_Weekly Report'!E47 -> 0 | F47: ='Example_Weekly Report'!F47 -> 0 | G47: ='Example_Weekly Report'!G47 -> 0 | H47: ='Example_Weekly Report'!H47 -> 0 | I47: ='Example_Weekly Report'!I47 -> 0 | J47: ='Example_Weekly Report'!J47 -> 1 | ... AF47: ='Example_Weekly Report'!AF47 -> 261
